<?xml version="1.0"?>
<robot name="my_robot" xmlns:xacro="http://www.ros.org/wiki/xacro">

  <!-- 材质 -->
  <material name="green"><color rgba="0 0.6 0 1"/></material>
  <material name="white"><color rgba="1 1 1 1"/></material>
  <material name="gray"><color rgba="0.7 0.7 0.7 1"/></material>
  
  <gazebo>
    <plugin name="diff_drive_controller" filename="libgazebo_ros_diff_drive.so">
        <!-- 更新频率（单位：Hz） -->
        <update_rate>50</update_rate>

        <!-- 轮子的关节 -->
        <left_joint>base_left_wheel_joint</left_joint>
        <right_joint>base_right_wheel_joint</right_joint>

        <!-- 运动学参数 -->
        <wheel_separation>0.4</wheel_separation>
        <wheel_diameter>0.2</wheel_diameter>

        <!-- 输出 -->
        <publish_odom>true</publish_odom>
        <publish_odom_tf>true</publish_odom_tf>
        <publish_wheel_tf>true</publish_wheel_tf>

        <odometry_topic>odom</odometry_topic>
        <odometry_frame>odom</odometry_frame>
        <robot_base_frame>base_footprint</robot_base_frame>

        <!-- 输入 -->
        <command_topic>cmd_vel</command_topic>
    </plugin>
  </gazebo>


  <!-- base_link -->
  <link name="base_link">
    <visual>
      <geometry><box size="0.6 0.4 0.2"/></geometry>
      <origin xyz="0 0 0.1" rpy="0 0 0"/>
      <material name="green"/>
    </visual>
    <collision>
      <geometry><box size="0.6 0.4 0.2"/></geometry>
      <origin xyz="0 0 0.1" rpy="0 0 0"/>
    </collision>
    <inertial>
      <mass value="5.0"/>
      <origin xyz="0 0 0.1" rpy="0 0 0"/>
      <inertia ixx="0.1" ixy="0" ixz="0" iyy="0.1" iyz="0" izz="0.1"/>
    </inertial>
  </link>

  <!-- lidar -->
  <link name="lidar">
    <visual>
      <geometry><cylinder radius="0.1" length="0.05"/></geometry>
      <origin xyz="0 0 0" rpy="0 0 0"/>
      <material name="white"/>
    </visual>
    <collision>
      <geometry><cylinder radius="0.1" length="0.05"/></geometry>
      <origin xyz="0 0 0" rpy="0 0 0"/>
    </collision>
    <inertial>
      <mass value="1.0"/>
      <origin xyz="0 0 0" rpy="0 0 0"/>
      <inertia ixx="0.01" ixy="0" ixz="0" iyy="0.01" iyz="0" izz="0.01"/>
    </inertial>
  </link>

  <!-- left_wheel -->
  <link name="left_wheel">
    <visual>
      <geometry><cylinder radius="0.1" length="0.05"/></geometry>
      <origin xyz="0 0 0.025" rpy="0 0 0"/>
      <material name="gray"/>
    </visual>
    <collision>
      <geometry><cylinder radius="0.1" length="0.05"/></geometry>
      <origin xyz="0 0 0.025" rpy="0 0 0"/>
    </collision>
    <inertial>
      <mass value="1.0"/>
      <origin xyz="0 0 0.025" rpy="0 0 0"/>
      <inertia ixx="0.01" ixy="0" ixz="0" iyy="0.01" iyz="0" izz="0.01"/>
    </inertial>
  </link>

  <!-- right_wheel -->
  <link name="right_wheel">
    <visual>
      <geometry><cylinder radius="0.1" length="0.05"/></geometry>
      <origin xyz="0 0 0.025" rpy="0 0 0"/>
      <material name="gray"/>
    </visual>
    <collision>
      <geometry><cylinder radius="0.1" length="0.05"/></geometry>
      <origin xyz="0 0 0.025" rpy="0 0 0"/>
    </collision>
    <inertial>
      <mass value="1.0"/>
      <origin xyz="0 0 0.025" rpy="0 0 0"/>
      <inertia ixx="0.01" ixy="0" ixz="0" iyy="0.01" iyz="0" izz="0.01"/>
    </inertial>
  </link>

  <!-- caster_wheel -->
  <link name="caster_wheel">
    <visual>
      <geometry><sphere radius="0.05"/></geometry>
      <origin xyz="0 0 0" rpy="0 0 0"/>
      <material name="gray"/>
    </visual>
    <collision>
      <geometry><sphere radius="0.05"/></geometry>
      <origin xyz="0 0 0" rpy="0 0 0"/>
    </collision>
    <inertial>
      <mass value="1.0"/>
      <origin xyz="0 0 0" rpy="0 0 0"/>
      <inertia ixx="0.005" ixy="0" ixz="0" iyy="0.005" iyz="0" izz="0.005"/>
    </inertial>
  </link>

  <!-- 虚拟 link -->
  <link name="base_footprint"/>

  <!-- joints -->
  <joint name="base_lidar_joint" type="fixed">
    <parent link="base_link"/>
    <child link="lidar"/>
    <origin xyz="0.15 0 0.225" rpy="0 0 0"/>
  </joint>

  <joint name="base_left_wheel_joint" type="continuous">
    <parent link="base_link"/>
    <child link="left_wheel"/>
    <origin xyz="-0.15 0.2 0" rpy="${-pi / 2.0} 0 0"/>
    <axis xyz="0 0 1"/>
  </joint>

  <joint name="base_right_wheel_joint" type="continuous">
    <parent link="base_link"/>
    <child link="right_wheel"/>
    <origin xyz="-0.15 -0.25 0" rpy="${-pi / 2.0} 0 0"/>
    <axis xyz="0 0 1"/>
  </joint>

  <joint name="base_caster_wheel_joint" type="fixed">
    <parent link="base_link"/>
    <child link="caster_wheel"/>
    <origin xyz="0.2 0 -0.05" rpy="0 0 0"/>
  </joint>

  <joint name="base_joint" type="fixed">
    <parent link="base_footprint"/>
    <child link="base_link"/>
    <origin xyz="0 0 0.1" rpy="0 0 0"/>
  </joint>
  
  <gazebo reference="base_link">
      <material>Gazebo/Green</material>
  </gazebo>
  
  <gazebo reference="caster_wheel">
      <material>Gazebo/Red</material>
  </gazebo>
  
  <gazebo reference="left_wheel">
      <material>Gazebo/Grey</material>
  </gazebo>
  
  <gazebo reference="right_wheel">
      <material>Gazebo/Grey</material>
  </gazebo>
  
  <gazebo reference="lidar">
      <material>Gazebo/Green</material>
  </gazebo>
  
</robot>
